<?xml version="1.0"?>
<robot name="diff_drive" xmlns:xacro="http://www.ros.org/wiki/xacro">
  <material name="orange">
    <color rgba="0.8 0.4 0.0 1.0"/>
  </material>

  <material name="black">
    <color rgba="0 0 0 1.0"/>
  </material>

  <material name="white">
    <color rgba="1 1 1 1.0"/>
  </material>

  <link name="chassis">
    <collision>
      <origin xyz="-0.151427 -0 0.5" rpy="0 0 0"/>
      <geometry>
        <box size="2.01142 1 0.568726"/>
      </geometry>
    </collision>

    <visual>
      <origin xyz="-0.151427 -0 0.5" rpy="0 0 0"/>
      <geometry>
        <box size="2.01142 1 0.568726"/>
      </geometry>
      <material name="orange"/>
    </visual>

    <inertial>
      <origin xyz="-0.151427 -0 0.5" rpy="0 0 0"/>
      <mass value="1.14395"/>
      <inertia
        ixx="0.126164"
        ixy="0.0"
        ixz="0.0"
        iyy="0.416519"
        iyz="0.0"
        izz="0.481014"/>
    </inertial>
  </link>

  <joint name="left_wheel_joint" type="continuous">
    <origin xyz="0.554283 0.625029 0.3" rpy="-1.5707 0 0"/>
    <parent link="chassis"/>
    <child link="left_wheel"/>
    <axis xyz="0 0 1"/>
    <dynamics damping="0.2"/>
  </joint>

  <link name="left_wheel">
    <collision>
      <geometry>
        <sphere radius="0.3"/>
      </geometry>
    </collision>

    <visual>
      <geometry>
        <sphere radius="0.3"/>
      </geometry>
      <material name="black"/>
    </visual>

    <inertial>
      <mass value="2"/>
      <inertia ixx="0.145833"
               ixy="0.0"
               ixz="0.0"
               iyy="0.145833"
               iyz="0.0"
               izz="0.125"/>
    </inertial>
  </link>

  <joint name="right_wheel_joint" type="continuous">
    <origin xyz="0.554283 -0.625029 0.3" rpy="-1.5707 0 0"/>
    <parent link="chassis"/>
    <child link="right_wheel"/>
    <axis xyz="0 0 1"/>
    <dynamics damping="0.2"/>
  </joint>

  <link name="right_wheel">
    <collision>
      <geometry>
        <sphere radius="0.3"/>
      </geometry>
    </collision>

    <visual>
      <geometry>
        <sphere radius="0.3"/>
      </geometry>
      <material name="black"/>
    </visual>

    <inertial>
      <mass value="2"/>
      <inertia ixx="0.145833"
               ixy="0.0"
               ixz="0.0"
               iyy="0.145833"
               iyz="0.0"
               izz="0.125"/>
      </inertial>
  </link>

  <joint name="caster_joint" type="fixed">
    <origin xyz="-0.957138 -0 0.2" rpy="0 0 0"/>
    <parent link="chassis"/>
    <child link="caster"/>
  </joint>

  <link name="caster">
    <collision>
      <geometry>
        <sphere radius="0.2"/>
      </geometry>
    </collision>

    <visual>
      <geometry>
        <sphere radius="0.2"/>
      </geometry>
      <material name="white"/>
    </visual>

    <inertial>
      <origin xyz="-0.957138 -0 0.2" rpy="0 0 0"/>
      <mass value="0.005"/>
      <inertia
        ixx="0.1"
        ixy="0.0"
        ixz="0.0"
        iyy="0.1"
        iyz="0.0"
        izz="0.1"/>
    </inertial>
  </link>

  <link name="camera">
    <visual>
      <origin xyz="0 0 0.8" rpy="0 0 0"/>
      <geometry>
        <box size="0.1 0.1 0.1"/>
      </geometry>
      <material name="black"/>
    </visual>
  </link>
 
</robot>